Workbook

Sheet README
A1: GNMA Project Loan Prepayment Model
A3: PURPOSE
A4: This workbook predicts monthly SMM (Single Monthly Mortality) and annualized CPR (Conditional Prepayment Rate) for individual GNMA multifamily project loans, then aggregates loans up to the GNR REMIC deal level so deals can be compared and the drivers of speed differences can be isolated.
A6: HOW TO USE
A7: 1. Open the Loan_Input sheet.
A8: 2. Replace the demo data (rows 2 and below) with your own loan-level data. At minimum you need: deal_id, loan_rate, upb, dates (origination, maturity, lockout end, prepay end), prepay penalty period, FHA program code, affordable status, modified/non-level/mature flags, period (YYYYMM). All formulas to the right derive features and predict CPR automatically.
A9: 3. Yellow cells are user input. Green cells are derived/computed. Orange cells are per-component attribution.
A10: 4. The Deal_Summary sheet aggregates loans by deal_id with weighted averages. The Deal_Comparison sheet displays the underlying drivers of CPR differences across deals side-by-side.
A11: 5. To override a model coefficient (e.g. for a stress scenario), edit the corresponding cell on Parameters.
A13: MODEL ARCHITECTURE
A14: Trained on 932,014 loan-month observations from 201812 through 202406 (8,881 voluntary prepay events). Held-out test: 308,876 observations from 202407 through 202603.
A16: Functional form: logistic regression on engineered piecewise-linear splines. log( SMM/(1-SMM) ) = intercept + Σ contributions. Each contribution maps cleanly to an Excel formula and to a CPR attribution.
... A50: Blue cells = parameter / coefficient

Sheet Parameters
A1: Parameter | B1: Value | C1: Description
A2: INTERCEPT | B2: -6.5830653 | C2: Logistic intercept; baseline log-odds when all features = 0.
A3: OPTIONAL_CPR_SCALAR | B3: 1 | C3: Multiplier on final predicted SMM. Use 1.0 for the unbiased model; use <1 to dampen if you believe the regime is more out-of-money than training; >1 for stress.
A5: Component | B5: Feature | C5: Coefficient | D5: Description
A6: REFI | B6: refi_lin | C6: 0.0043203709 | D6: Linear slope of refi incentive in bps
A7: REFI | B7: refi_k-150 | C7: 0.0022721146 | D7: Hinge: extra slope past −150 bps incentive
A8: REFI | B8: refi_k-50 | C8: 0.0017670998 | D8: Hinge: extra slope past −50 bps incentive
A9: REFI | B9: refi_k0 | C9: 0.00091223458 | D9: Hinge: extra slope past 0 bps (at-money)
A10: REFI | B10: refi_k50 | C10: -0.0015626207 | D10: Hinge: extra slope past +50 bps incentive
A11: REFI | B11: refi_k100 | C11: -0.0034164295 | D11: Hinge: extra slope past +100 bps incentive
A12: REFI | B12: refi_k150 | C12: -0.0023538754 | D12: Hinge: extra slope past +150 bps incentive
A13: REFI | B13: refi_k250 | C13: -0.00097698167 | D13: Hinge: extra slope past +250 bps incentive
A14: AGE | B14: age_lin | C14: 0.0059010869 | D14: Linear slope of loan age (months)
A15: AGE | B15: age_k12 | C15: 0.005360449 | D15: Hinge: extra slope past 12 months age
A16: AGE | B16: age_k36 | C16: 0.00056806319 | D16: Hinge: extra slope past 36 months age
A17: AGE | B17: age_k60 | C17: -0.0029967448 | D17: Hinge: extra slope past 60 months age
... A59: POOL | B59: is_rx_pool | C59: -0.47853494 | D59: Pool type = RX (Mark-to-Market)

Sheet PLC_Rates
A1: period | B1: PLC_rate_bps
A2: 201812 | B2: 354
A3: 201901 | B3: 352
A4: 201902 | B4: 355
A5: 201903 | B5: 328
A6: 201904 | B6: 319
A7: 201905 | B7: 279
A8: 201906 | B8: 276
A9: 201907 | B9: 264
A10: 201908 | B10: 228
A11: 201909 | B11: 245
A12: 201910 | B12: 242
A13: 201911 | B13: 262
... A89: 202603 | B89: 490.5

Sheet Vintage_Rates
A1: vintage_year | B1: median_loan_rate_pct | C1: n_loans
A2: 1990 | B2: 4.52 | C2: 1
A3: 1991 | B3: 3.785 | C3: 2
A4: 1992 | B4: 3.78 | C4: 4
A5: 1994 | B5: 3.58 | C5: 7
A6: 1995 | B6: 4.22 | C6: 9
A7: 1996 | B7: 3.6975 | C7: 4
A8: 1997 | B8: 3.53 | C8: 10
A9: 1998 | B9: 5.85 | C9: 19
A10: 1999 | B10: 6 | C10: 28
A11: 2000 | B11: 6 | C11: 13
A12: 2001 | B12: 7.5 | C12: 66
A13: 2002 | B13: 6.75 | C13: 139
... A37: 2026 | B37: 5.5 | C37: 106

Sheet FHA_Lookup
A1: search_substring | B1: fha_category | C1: loan_purpose
A2: 538 | B2: 538 | C2: 538
A3: 232 | B3: 232 | C3: NC
A4: 223(F) | B4: 223f | C4: RP
A5: 223F | B5: 223f | C5: RP
A6: 223(A) | B6: 223a7 | C6: RP
A7: 223A | B7: 223a7 | C7: RP
A8: 221(D) | B8: 221d4 | C8: NC
A9: 221D | B9: 221d4 | C9: NC
A10: 220 | B10: 220 | C10: NC
A11: 241 | B11: 241 | C11: NC

Sheet Loan_Input
A1: LOAN INPUTS — replace with your data | AA1: DERIVED FEATURES — auto-computed | BF1: LOG-ODDS CONTRIBUTIONS — by component | BS1: PREDICTED CPR & ATTRIBUTION
A2: deal_id | B2: pool_cusip | C2: pool_type | D2: issuer_name | E2: loan_id | F2: period | G2: loan_rate_pct | H2: upb | I2: loan_term_months | J2: origination_date | K2: loan_maturity_date | L2: lockout_end_date | M2: prepay_end_date | N2: prepay_premium_period_yrs | O2: fha_program_code | P2: affordable_status | Q2: modified_ind | R2: non_level_ind | S2: mature_loan_flag | T2: property_state | U2: num_units | V2: plc_rate_bps_input | W2: loan_age_months_input | X2: vintage_year_input | Y2: sato_bps_input | Z2: prepay_penalty_points_input | AA2: loan_age_months | AB2: months_to_maturity | AC2: months_post_lockout | AD2: in_lockout | AE2: in_prepay_penalty | AF2: past_all_restrictions | AG2: vintage_year | AH2: vintage_median_rate | AI2: sato_bps | AJ2: plc_rate_bps | AK2: prepay_penalty_points | AL2: gross_refi_incentive_bps | AM2: refi_incentive_bps | AN2: upb_millions | AO2: fha_category | AP2: loan_purpose | AQ2: is_nc | AR2: aff_aff | AS2: aff_baf | AT2: aff_mkt | AU2: fha_221d4 | AV2: fha_223a7 | AW2: fha_232 | AX2: fha_538 | AY2: fha_241 | AZ2: fha_220 | BA2: fha_other | BB2: is_lm_pool | BC2: is_pn_pool | BD2: is_ls_pool | BE2: is_rx_pool | BF2: REFI_logodds | BG2: AGE_logodds | BH2: PEN_logodds | BI2: SATO_logodds | BJ2: SIZE_logodds | BK2: M2M_logodds | BL2: MPL_logodds | BM2: INTERACT_logodds | BN2: PHASE_logodds | BO2: FHA_logodds | BP2: PURPOSE_logodds | BQ2: AFF_logodds | BR2: POOL_logodds | BS2: intercept_logodds | BT2: total_logodds | BU2: predicted_SMM | BV2: predicted_CPR_pct | BW2: baseline_CPR_pct | BX2: CPR_attr_REFI | BY2: CPR_attr_AGE | BZ2: CPR_attr_PEN | CA2: CPR_attr_SATO | CB2: CPR_attr_SIZE | CC2: CPR_attr_M2M | CD2: CPR_attr_MPL | CE2: CPR_attr_INTERACT | CF2: CPR_attr_PHASE | CG2: CPR_attr_FHA | CH2: CPR_attr_PURPOSE | CI2: CPR_attr_AFF | CJ2: CPR_attr_POOL
A3: GNR_2024_NEW | B3: 3618M3XD2 | C3: PN | D3: VIUM CAPITAL MORTGAGE, LLC. | E3: 3618M3XD2_000000006422141 | F3: 202603 | G3: 5.69 | H3: 24499232 | I3: 420 | J3: 20251201 | K3: 20610101 | M3: 20360201 | N3: 10 | O3: 232/223(F) | T3: LA | U3: 63 | V3: 490.5 | W3: 3 | X3: 2025 | Y3: -13 | Z3: 10 | AA3: =IF(ISNUMBER(W3),W3,IFERROR(MAX(0,(VALUE(LEFT(F3,4))-VALUE(LEFT(TEXT(J3,"00000000"),4)))*12+(VALUE(MID(F3,5,2))-VALUE(MID(TEXT(J3,"00000000"),5,2)))),"")) | AB3: =IFERROR((VALUE(LEFT(TEXT(K3,"00000000"),4))-VALUE(LEFT(F3,4)))*12+(VALUE(MID(TEXT(K3,"00000000"),5,2))-VALUE(MID(F3,5,2))),"") | AC3: =IF(OR(L3="",NOT(ISNUMBER(L3))),0,MAX(0,MIN(60,(VALUE(LEFT(F3,4))-VALUE(LEFT(TEXT(L3,"00000000"),4)))*12+(VALUE(MID(F3,5,2))-VALUE(MID(TEXT(L3,"00000000"),5,2)))))) | AD3: =IF(OR(L3="",NOT(ISNUMBER(L3))),0,IF(VALUE(F3)<VALUE(LEFT(TEXT(L3,"00000000"),6)),1,0)) | AE3: =IF(OR(M3="",NOT(ISNUMBER(M3))),0,IF(VALUE(F3)<VALUE(LEFT(TEXT(M3,"00000000"),6)),1,0)) | AF3: =IF(AND(AD3=0,AE3=0),1,0) | AG3: =IF(ISNUMBER(X3),X3,IFERROR(VALUE(LEFT(TEXT(J3,"00000000"),4)),"")) | AH3: =IFERROR(XLOOKUP(AG3,Vintage_Rates!$A$2:$A$1000,Vintage_Rates!$B$2:$B$1000,""),"") | AI3: =IF(ISNUMBER(Y3),Y3,IFERROR((G3-AH3)*100,"")) | AJ3: =IF(ISNUMBER(V3),V3,IFERROR(XLOOKUP(VALUE(F3),PLC_Rates!$A$2:$A$1000,PLC_Rates!$B$2:$B$1000,""),"")) | AK3: =IF(ISNUMBER(Z3),Z3,IF(AE3=0,0,MAX(0,MIN(10,((VALUE(LEFT(TEXT(M3,"00000000"),4))-VALUE(LEFT(F3,4)))*12+(VALUE(MID(TEXT(M3,"00000000"),5,2))-VALUE(MID(F3,5,2))))/12)))) | AL3: =IFERROR(G3*100-AJ3,"") | AM3: =IFERROR(G3*100-(AJ3+(1+AK3)*12.5),"") | AN3: =IFERROR(MIN(H3/1000000,100),"") | AO3: =IFERROR(INDEX(FHA_Lookup!$B$2:$B$11,MATCH(TRUE,ISNUMBER(SEARCH(FHA_Lookup!$A$2:$A$11,UPPER(SUBSTITUTE(O3," ","")))),0)),"OTHER") | AP3: =IFERROR(INDEX(FHA_Lookup!$C$2:$C$11,MATCH(TRUE,ISNUMBER(SEARCH(FHA_Lookup!$A$2:$A$11,UPPER(SUBSTITUTE(O3," ","")))),0)),"OTHER") | AQ3: =IF(AP3="NC",1,0) | AR3: =IF(UPPER(TRIM(P3))="AFF",1,0) | AS3: =IF(UPPER(TRIM(P3))="BAF",1,0) | AT3: =IF(UPPER(TRIM(P3))="MKT",1,0) | AU3: =IF(AO3="221d4",1,0) | AV3: =IF(AO3="223a7",1,0) | AW3: =IF(AO3="232",1,0) | AX3: =IF(AO3="538",1,0) | AY3: =IF(AO3="241",1,0) | AZ3: =IF(AO3="220",1,0) | BA3: =IF(AO3="OTHER",1,0) | BB3: =IF(UPPER(TRIM(C3))="LM",1,0) | BC3: =IF(UPPER(TRIM(C3))="PN",1,0) | BD3: =IF(UPPER(TRIM(C3))="LS",1,0) | BE3: =IF(UPPER(TRIM(C3))="RX",1,0) | BF3: =IFERROR((Parameters!$C$6*AM3+Parameters!$C$7*MAX(AM3-(-150),0)+Parameters!$C$8*MAX(AM3-(-50),0)+Parameters!$C$9*MAX(AM3-(0),0)+Parameters!$C$10*MAX(AM3-(50),0)+Parameters!$C$11*MAX(AM3-(100),0)+Parameters!$C$12*MAX(AM3-(150),0)+Parameters!$C$13*MAX(AM3-(250),0)),0) | BG3: =IFERROR((Parameters!$C$14*AA3+Parameters!$C$15*MAX(AA3-(12),0)+Parameters!$C$16*MAX(AA3-(36),0)+Parameters!$C$17*MAX(AA3-(60),0)+Parameters!$C$18*MAX(AA3-(84),0)+Parameters!$C$19*MAX(AA3-(120),0)+Parameters!$C$20*MAX(AA3-(180),0)),0) | BH3: =IFERROR((Parameters!$C$21*AK3+Parameters!$C$22*MAX(AK3-(0),0)+Parameters!$C$23*MAX(AK3-(2),0)+Parameters!$C$24*MAX(AK3-(5),0)+Parameters!$C$25*MAX(AK3-(8),0)),0) | BI3: =IFERROR((Parameters!$C$26*AI3+Parameters!$C$27*MAX(AI3-(-100),0)+Parameters!$C$28*MAX(AI3-(-25),0)+Parameters!$C$29*MAX(AI3-(25),0)+Parameters!$C$30*MAX(AI3-(100),0)),0) | BJ3: =IFERROR((Parameters!$C$31*AN3+Parameters!$C$32*MAX(AN3-(2),0)+Parameters!$C$33*MAX(AN3-(10),0)+Parameters!$C$34*MAX(AN3-(25),0)),0) | BK3: =IFERROR((Parameters!$C$35*AB3+Parameters!$C$36*MAX(AB3-(12),0)+Parameters!$C$37*MAX(AB3-(24),0)+Parameters!$C$38*MAX(AB3-(60),0)),0) | BL3: =IFERROR((Parameters!$C$39*AC3+Parameters!$C$40*MAX(AC3-(6),0)+Parameters!$C$41*MAX(AC3-(12),0)+Parameters!$C$42*MAX(AC3-(24),0)),0) | BM3: =IFERROR(Parameters!$C$43*(MAX(AM3,0)*MIN(MAX(AK3,0),10))/100,0) | BN3: =Parameters!$C$44*AE3 | BO3: =Parameters!$C$45*AU3 + Parameters!$C$46*AV3 + Parameters!$C$47*AW3 + Parameters!$C$48*AX3 + Parameters!$C$49*AY3 + Parameters!$C$50*AZ3 + Parameters!$C$51*BA3 | BP3: =Parameters!$C$52*AQ3 | BQ3: =Parameters!$C$53*AR3+Parameters!$C$54*AS3+Parameters!$C$55*AT3 | BR3: =Parameters!$C$56*BB3+Parameters!$C$57*BC3+Parameters!$C$58*BD3+Parameters!$C$59*BE3 | BS3: =Parameters!$B$2 | BT3: =BS3+BF3 + BG3 + BH3 + BI3 + BJ3 + BK3 + BL3 + BM3 + BN3 + BO3 + BP3 + BQ3 + BR3 | BU3: =IF(AD3=1,0,1/(1+EXP(-BT3))*Parameters!$B$3) | BV3: =(1-(1-BU3)^12)*100 | BW3: =IF(AD3=1,0,(1-(1-1/(1+EXP(-Parameters!$B$2)))^12)*100) | BX3: =IF(AD3=1,0,BV3-(1-(1-(1/(1+EXP(-(BT3-BF3)))*Parameters!$B$3))^12)*100) | BY3: =IF(AD3=1,0,BV3-(1-(1-(1/(1+EXP(-(BT3-BG3)))*Parameters!$B$3))^12)*100) | BZ3: =IF(AD3=1,0,BV3-(1-(1-(1/(1+EXP(-(BT3-BH3)))*Parameters!$B$3))^12)*100) | CA3: =IF(AD3=1,0,BV3-(1-(1-(1/(1+EXP(-(BT3-BI3)))*Parameters!$B$3))^12)*100) | CB3: =IF(AD3=1,0,BV3-(1-(1-(1/(1+EXP(-(BT3-BJ3)))*Parameters!$B$3))^12)*100) | CC3: =IF(AD3=1,0,BV3-(1-(1-(1/(1+EXP(-(BT3-BK3)))*Parameters!$B$3))^12)*100) | CD3: =IF(AD3=1,0,BV3-(1-(1-(1/(1+EXP(-(BT3-BL3)))*Parameters!$B$3))^12)*100) | CE3: =IF(AD3=1,0,BV3-(1-(1-(1/(1+EXP(-(BT3-BM3)))*Parameters!$B$3))^12)*100) | CF3: =IF(AD3=1,0,BV3-(1-(1-(1/(1+EXP(-(BT3-BN3)))*Parameters!$B$3))^12)*100) | CG3: =IF(AD3=1,0,BV3-(1-(1-(1/(1+EXP(-(BT3-BO3)))*Parameters!$B$3))^12)*100) | CH3: =IF(AD3=1,0,BV3-(1-(1-(1/(1+EXP(-(BT3-BP3)))*Parameters!$B$3))^12)*100) | CI3: =IF(AD3=1,0,BV3-(1-(1-(1/(1+EXP(-(BT3-BQ3)))*Parameters!$B$3))^12)*100) | CJ3: =IF(AD3=1,0,BV3-(1-(1-(1/(1+EXP(-(BT3-BR3)))*Parameters!$B$3))^12)*100)
A4: GNR_2024_NEW | B4: 3618K96G4 | C4: PN | D4: GREYSTONE FUNDING COMPANY LLC | E4: 3618K96G4_000000011622044 | F4: 202603 | G4: 5.89 | H4: 12467559 | I4: 420 | J4: 20250401 | K4: 20600501 | M4: 20350601 | N4: 10 | O4: 232/223(F) | T4: NM | U4: 32 | V4: 490.5 | W4: 11 | X4: 2025 | Y4: 7 | Z4: 10 | AA4: =IF(ISNUMBER(W4),W4,IFERROR(MAX(0,(VALUE(LEFT(F4,4))-VALUE(LEFT(TEXT(J4,"00000000"),4)))*12+(VALUE(MID(F4,5,2))-VALUE(MID(TEXT(J4,"00000000"),5,2)))),"")) | AB4: =IFERROR((VALUE(LEFT(TEXT(K4,"00000000"),4))-VALUE(LEFT(F4,4)))*12+(VALUE(MID(TEXT(K4,"00000000"),5,2))-VALUE(MID(F4,5,2))),"") | AC4: =IF(OR(L4="",NOT(ISNUMBER(L4))),0,MAX(0,MIN(60,(VALUE(LEFT(F4,4))-VALUE(LEFT(TEXT(L4,"00000000"),4)))*12+(VALUE(MID(F4,5,2))-VALUE(MID(TEXT(L4,"00000000"),5,2)))))) | AD4: =IF(OR(L4="",NOT(ISNUMBER(L4))),0,IF(VALUE(F4)<VALUE(LEFT(TEXT(L4,"00000000"),6)),1,0)) | AE4: =IF(OR(M4="",NOT(ISNUMBER(M4))),0,IF(VALUE(F4)<VALUE(LEFT(TEXT(M4,"00000000"),6)),1,0)) | AF4: =IF(AND(AD4=0,AE4=0),1,0) | AG4: =IF(ISNUMBER(X4),X4,IFERROR(VALUE(LEFT(TEXT(J4,"00000000"),4)),"")) | AH4: =IFERROR(XLOOKUP(AG4,Vintage_Rates!$A$2:$A$1000,Vintage_Rates!$B$2:$B$1000,""),"") | AI4: =IF(ISNUMBER(Y4),Y4,IFERROR((G4-AH4)*100,"")) | AJ4: =IF(ISNUMBER(V4),V4,IFERROR(XLOOKUP(VALUE(F4),PLC_Rates!$A$2:$A$1000,PLC_Rates!$B$2:$B$1000,""),"")) | AK4: =IF(ISNUMBER(Z4),Z4,IF(AE4=0,0,MAX(0,MIN(10,((VALUE(LEFT(TEXT(M4,"00000000"),4))-VALUE(LEFT(F4,4)))*12+(VALUE(MID(TEXT(M4,"00000000"),5,2))-VALUE(MID(F4,5,2))))/12)))) | AL4: =IFERROR(G4*100-AJ4,"") | AM4: =IFERROR(G4*100-(AJ4+(1+AK4)*12.5),"") | AN4: =IFERROR(MIN(H4/1000000,100),"") | AO4: =IFERROR(INDEX(FHA_Lookup!$B$2:$B$11,MATCH(TRUE,ISNUMBER(SEARCH(FHA_Lookup!$A$2:$A$11,UPPER(SUBSTITUTE(O4," ","")))),0)),"OTHER") | AP4: =IFERROR(INDEX(FHA_Lookup!$C$2:$C$11,MATCH(TRUE,ISNUMBER(SEARCH(FHA_Lookup!$A$2:$A$11,UPPER(SUBSTITUTE(O4," ","")))),0)),"OTHER") | AQ4: =IF(AP4="NC",1,0) | AR4: =IF(UPPER(TRIM(P4))="AFF",1,0) | AS4: =IF(UPPER(TRIM(P4))="BAF",1,0) | AT4: =IF(UPPER(TRIM(P4))="MKT",1,0) | AU4: =IF(AO4="221d4",1,0) | AV4: =IF(AO4="223a7",1,0) | AW4: =IF(AO4="232",1,0) | AX4: =IF(AO4="538",1,0) | AY4: =IF(AO4="241",1,0) | AZ4: =IF(AO4="220",1,0) | BA4: =IF(AO4="OTHER",1,0) | BB4: =IF(UPPER(TRIM(C4))="LM",1,0) | BC4: =IF(UPPER(TRIM(C4))="PN",1,0) | BD4: =IF(UPPER(TRIM(C4))="LS",1,0) | BE4: =IF(UPPER(TRIM(C4))="RX",1,0) | BF4: =IFERROR((Parameters!$C$6*AM4+Parameters!$C$7*MAX(AM4-(-150),0)+Parameters!$C$8*MAX(AM4-(-50),0)+Parameters!$C$9*MAX(AM4-(0),0)+Parameters!$C$10*MAX(AM4-(50),0)+Parameters!$C$11*MAX(AM4-(100),0)+Parameters!$C$12*MAX(AM4-(150),0)+Parameters!$C$13*MAX(AM4-(250),0)),0) | BG4: =IFERROR((Parameters!$C$14*AA4+Parameters!$C$15*MAX(AA4-(12),0)+Parameters!$C$16*MAX(AA4-(36),0)+Parameters!$C$17*MAX(AA4-(60),0)+Parameters!$C$18*MAX(AA4-(84),0)+Parameters!$C$19*MAX(AA4-(120),0)+Parameters!$C$20*MAX(AA4-(180),0)),0) | BH4: =IFERROR((Parameters!$C$21*AK4+Parameters!$C$22*MAX(AK4-(0),0)+Parameters!$C$23*MAX(AK4-(2),0)+Parameters!$C$24*MAX(AK4-(5),0)+Parameters!$C$25*MAX(AK4-(8),0)),0) | BI4: =IFERROR((Parameters!$C$26*AI4+Parameters!$C$27*MAX(AI4-(-100),0)+Parameters!$C$28*MAX(AI4-(-25),0)+Parameters!$C$29*MAX(AI4-(25),0)+Parameters!$C$30*MAX(AI4-(100),0)),0) | BJ4: =IFERROR((Parameters!$C$31*AN4+Parameters!$C$32*MAX(AN4-(2),0)+Parameters!$C$33*MAX(AN4-(10),0)+Parameters!$C$34*MAX(AN4-(25),0)),0) | BK4: =IFERROR((Parameters!$C$35*AB4+Parameters!$C$36*MAX(AB4-(12),0)+Parameters!$C$37*MAX(AB4-(24),0)+Parameters!$C$38*MAX(AB4-(60),0)),0) | BL4: =IFERROR((Parameters!$C$39*AC4+Parameters!$C$40*MAX(AC4-(6),0)+Parameters!$C$41*MAX(AC4-(12),0)+Parameters!$C$42*MAX(AC4-(24),0)),0) | BM4: =IFERROR(Parameters!$C$43*(MAX(AM4,0)*MIN(MAX(AK4,0),10))/100,0) | BN4: =Parameters!$C$44*AE4 | BO4: =Parameters!$C$45*AU4 + Parameters!$C$46*AV4 + Parameters!$C$47*AW4 + Parameters!$C$48*AX4 + Parameters!$C$49*AY4 + Parameters!$C$50*AZ4 + Parameters!$C$51*BA4 | BP4: =Parameters!$C$52*AQ4 | BQ4: =Parameters!$C$53*AR4+Parameters!$C$54*AS4+Parameters!$C$55*AT4 | BR4: =Parameters!$C$56*BB4+Parameters!$C$57*BC4+Parameters!$C$58*BD4+Parameters!$C$59*BE4 | BS4: =Parameters!$B$2 | BT4: =BS4+BF4 + BG4 + BH4 + BI4 + BJ4 + BK4 + BL4 + BM4 + BN4 + BO4 + BP4 + BQ4 + BR4 | BU4: =IF(AD4=1,0,1/(1+EXP(-BT4))*Parameters!$B$3) | BV4: =(1-(1-BU4)^12)*100 | BW4: =IF(AD4=1,0,(1-(1-1/(1+EXP(-Parameters!$B$2)))^12)*100) | BX4: =IF(AD4=1,0,BV4-(1-(1-(1/(1+EXP(-(BT4-BF4)))*Parameters!$B$3))^12)*100) | BY4: =IF(AD4=1,0,BV4-(1-(1-(1/(1+EXP(-(BT4-BG4)))*Parameters!$B$3))^12)*100) | BZ4: =IF(AD4=1,0,BV4-(1-(1-(1/(1+EXP(-(BT4-BH4)))*Parameters!$B$3))^12)*100) | CA4: =IF(AD4=1,0,BV4-(1-(1-(1/(1+EXP(-(BT4-BI4)))*Parameters!$B$3))^12)*100) | CB4: =IF(AD4=1,0,BV4-(1-(1-(1/(1+EXP(-(BT4-BJ4)))*Parameters!$B$3))^12)*100) | CC4: =IF(AD4=1,0,BV4-(1-(1-(1/(1+EXP(-(BT4-BK4)))*Parameters!$B$3))^12)*100) | CD4: =IF(AD4=1,0,BV4-(1-(1-(1/(1+EXP(-(BT4-BL4)))*Parameters!$B$3))^12)*100) | CE4: =IF(AD4=1,0,BV4-(1-(1-(1/(1+EXP(-(BT4-BM4)))*Parameters!$B$3))^12)*100) | CF4: =IF(AD4=1,0,BV4-(1-(1-(1/(1+EXP(-(BT4-BN4)))*Parameters!$B$3))^12)*100) | CG4: =IF(AD4=1,0,BV4-(1-(1-(1/(1+EXP(-(BT4-BO4)))*Parameters!$B$3))^12)*100) | CH4: =IF(AD4=1,0,BV4-(1-(1-(1/(1+EXP(-(BT4-BP4)))*Parameters!$B$3))^12)*100) | CI4: =IF(AD4=1,0,BV4-(1-(1-(1/(1+EXP(-(BT4-BQ4)))*Parameters!$B$3))^12)*100) | CJ4: =IF(AD4=1,0,BV4-(1-(1-(1/(1+EXP(-(BT4-BR4)))*Parameters!$B$3))^12)*100)
A5: GNR_2024_NEW | B5: 3618FH2S0 | C5: PN | D5: NEWPOINT REAL ESTATE CAPITAL LLC | E5: 3618FH2S0_000000001711297 | F5: 202603 | G5: 5.98 | H5: 3566192.3 | I5: 420 | J5: 20240221 | K5: 20590301 | M5: 20340401 | N5: 10 | O5: 207/223(F) | P5: MKT | T5: CT | U5: 25 | V5: 490.5 | W5: 25 | X5: 2024 | Y5: 20 | Z5: 9 | AA5: =IF(ISNUMBER(W5),W5,IFERROR(MAX(0,(VALUE(LEFT(F5,4))-VALUE(LEFT(TEXT(J5,"00000000"),4)))*12+(VALUE(MID(F5,5,2))-VALUE(MID(TEXT(J5,"00000000"),5,2)))),"")) | AB5: =IFERROR((VALUE(LEFT(TEXT(K5,"00000000"),4))-VALUE(LEFT(F5,4)))*12+(VALUE(MID(TEXT(K5,"00000000"),5,2))-VALUE(MID(F5,5,2))),"") | AC5: =IF(OR(L5="",NOT(ISNUMBER(L5))),0,MAX(0,MIN(60,(VALUE(LEFT(F5,4))-VALUE(LEFT(TEXT(L5,"00000000"),4)))*12+(VALUE(MID(F5,5,2))-VALUE(MID(TEXT(L5,"00000000"),5,2)))))) | AD5: =IF(OR(L5="",NOT(ISNUMBER(L5))),0,IF(VALUE(F5)<VALUE(LEFT(TEXT(L5,"00000000"),6)),1,0)) | AE5: =IF(OR(M5="",NOT(ISNUMBER(M5))),0,IF(VALUE(F5)<VALUE(LEFT(TEXT(M5,"00000000"),6)),1,0)) | AF5: =IF(AND(AD5=0,AE5=0),1,0) | AG5: =IF(ISNUMBER(X5),X5,IFERROR(VALUE(LEFT(TEXT(J5,"00000000"),4)),"")) | AH5: =IFERROR(XLOOKUP(AG5,Vintage_Rates!$A$2:$A$1000,Vintage_Rates!$B$2:$B$1000,""),"") | AI5: =IF(ISNUMBER(Y5),Y5,IFERROR((G5-AH5)*100,"")) | AJ5: =IF(ISNUMBER(V5),V5,IFERROR(XLOOKUP(VALUE(F5),PLC_Rates!$A$2:$A$1000,PLC_Rates!$B$2:$B$1000,""),"")) | AK5: =IF(ISNUMBER(Z5),Z5,IF(AE5=0,0,MAX(0,MIN(10,((VALUE(LEFT(TEXT(M5,"00000000"),4))-VALUE(LEFT(F5,4)))*12+(VALUE(MID(TEXT(M5,"00000000"),5,2))-VALUE(MID(F5,5,2))))/12)))) | AL5: =IFERROR(G5*100-AJ5,"") | AM5: =IFERROR(G5*100-(AJ5+(1+AK5)*12.5),"") | AN5: =IFERROR(MIN(H5/1000000,100),"") | AO5: =IFERROR(INDEX(FHA_Lookup!$B$2:$B$11,MATCH(TRUE,ISNUMBER(SEARCH(FHA_Lookup!$A$2:$A$11,UPPER(SUBSTITUTE(O5," ","")))),0)),"OTHER") | AP5: =IFERROR(INDEX(FHA_Lookup!$C$2:$C$11,MATCH(TRUE,ISNUMBER(SEARCH(FHA_Lookup!$A$2:$A$11,UPPER(SUBSTITUTE(O5," ","")))),0)),"OTHER") | AQ5: =IF(AP5="NC",1,0) | AR5: =IF(UPPER(TRIM(P5))="AFF",1,0) | AS5: =IF(UPPER(TRIM(P5))="BAF",1,0) | AT5: =IF(UPPER(TRIM(P5))="MKT",1,0) | AU5: =IF(AO5="221d4",1,0) | AV5: =IF(AO5="223a7",1,0) | AW5: =IF(AO5="232",1,0) | AX5: =IF(AO5="538",1,0) | AY5: =IF(AO5="241",1,0) | AZ5: =IF(AO5="220",1,0) | BA5: =IF(AO5="OTHER",1,0) | BB5: =IF(UPPER(TRIM(C5))="LM",1,0) | BC5: =IF(UPPER(TRIM(C5))="PN",1,0) | BD5: =IF(UPPER(TRIM(C5))="LS",1,0) | BE5: =IF(UPPER(TRIM(C5))="RX",1,0) | BF5: =IFERROR((Parameters!$C$6*AM5+Parameters!$C$7*MAX(AM5-(-150),0)+Parameters!$C$8*MAX(AM5-(-50),0)+Parameters!$C$9*MAX(AM5-(0),0)+Parameters!$C$10*MAX(AM5-(50),0)+Parameters!$C$11*MAX(AM5-(100),0)+Parameters!$C$12*MAX(AM5-(150),0)+Parameters!$C$13*MAX(AM5-(250),0)),0) | BG5: =IFERROR((Parameters!$C$14*AA5+Parameters!$C$15*MAX(AA5-(12),0)+Parameters!$C$16*MAX(AA5-(36),0)+Parameters!$C$17*MAX(AA5-(60),0)+Parameters!$C$18*MAX(AA5-(84),0)+Parameters!$C$19*MAX(AA5-(120),0)+Parameters!$C$20*MAX(AA5-(180),0)),0) | BH5: =IFERROR((Parameters!$C$21*AK5+Parameters!$C$22*MAX(AK5-(0),0)+Parameters!$C$23*MAX(AK5-(2),0)+Parameters!$C$24*MAX(AK5-(5),0)+Parameters!$C$25*MAX(AK5-(8),0)),0) | BI5: =IFERROR((Parameters!$C$26*AI5+Parameters!$C$27*MAX(AI5-(-100),0)+Parameters!$C$28*MAX(AI5-(-25),0)+Parameters!$C$29*MAX(AI5-(25),0)+Parameters!$C$30*MAX(AI5-(100),0)),0) | BJ5: =IFERROR((Parameters!$C$31*AN5+Parameters!$C$32*MAX(AN5-(2),0)+Parameters!$C$33*MAX(AN5-(10),0)+Parameters!$C$34*MAX(AN5-(25),0)),0) | BK5: =IFERROR((Parameters!$C$35*AB5+Parameters!$C$36*MAX(AB5-(12),0)+Parameters!$C$37*MAX(AB5-(24),0)+Parameters!$C$38*MAX(AB5-(60),0)),0) | BL5: =IFERROR((Parameters!$C$39*AC5+Parameters!$C$40*MAX(AC5-(6),0)+Parameters!$C$41*MAX(AC5-(12),0)+Parameters!$C$42*MAX(AC5-(24),0)),0) | BM5: =IFERROR(Parameters!$C$43*(MAX(AM5,0)*MIN(MAX(AK5,0),10))/100,0) | BN5: =Parameters!$C$44*AE5 | BO5: =Parameters!$C$45*AU5 + Parameters!$C$46*AV5 + Parameters!$C$47*AW5 + Parameters!$C$48*AX5 + Parameters!$C$49*AY5 + Parameters!$C$50*AZ5 + Parameters!$C$51*BA5 | BP5: =Parameters!$C$52*AQ5 | BQ5: =Parameters!$C$53*AR5+Parameters!$C$54*AS5+Parameters!$C$55*AT5 | BR5: =Parameters!$C$56*BB5+Parameters!$C$57*BC5+Parameters!$C$58*BD5+Parameters!$C$59*BE5 | BS5: =Parameters!$B$2 | BT5: =BS5+BF5 + BG5 + BH5 + BI5 + BJ5 + BK5 + BL5 + BM5 + BN5 + BO5 + BP5 + BQ5 + BR5 | BU5: =IF(AD5=1,0,1/(1+EXP(-BT5))*Parameters!$B$3) | BV5: =(1-(1-BU5)^12)*100 | BW5: =IF(AD5=1,0,(1-(1-1/(1+EXP(-Parameters!$B$2)))^12)*100) | BX5: =IF(AD5=1,0,BV5-(1-(1-(1/(1+EXP(-(BT5-BF5)))*Parameters!$B$3))^12)*100) | BY5: =IF(AD5=1,0,BV5-(1-(1-(1/(1+EXP(-(BT5-BG5)))*Parameters!$B$3))^12)*100) | BZ5: =IF(AD5=1,0,BV5-(1-(1-(1/(1+EXP(-(BT5-BH5)))*Parameters!$B$3))^12)*100) | CA5: =IF(AD5=1,0,BV5-(1-(1-(1/(1+EXP(-(BT5-BI5)))*Parameters!$B$3))^12)*100) | CB5: =IF(AD5=1,0,BV5-(1-(1-(1/(1+EXP(-(BT5-BJ5)))*Parameters!$B$3))^12)*100) | CC5: =IF(AD5=1,0,BV5-(1-(1-(1/(1+EXP(-(BT5-BK5)))*Parameters!$B$3))^12)*100) | CD5: =IF(AD5=1,0,BV5-(1-(1-(1/(1+EXP(-(BT5-BL5)))*Parameters!$B$3))^12)*100) | CE5: =IF(AD5=1,0,BV5-(1-(1-(1/(1+EXP(-(BT5-BM5)))*Parameters!$B$3))^12)*100) | CF5: =IF(AD5=1,0,BV5-(1-(1-(1/(1+EXP(-(BT5-BN5)))*Parameters!$B$3))^12)*100) | CG5: =IF(AD5=1,0,BV5-(1-(1-(1/(1+EXP(-(BT5-BO5)))*Parameters!$B$3))^12)*100) | CH5: =IF(AD5=1,0,BV5-(1-(1-(1/(1+EXP(-(BT5-BP5)))*Parameters!$B$3))^12)*100) | CI5: =IF(AD5=1,0,BV5-(1-(1-(1/(1+EXP(-(BT5-BQ5)))*Parameters!$B$3))^12)*100) | CJ5: =IF(AD5=1,0,BV5-(1-(1-(1/(1+EXP(-(BT5-BR5)))*Parameters!$B$3))^12)*100)
A6: GNR_2024_NEW | B6: 3617XHQ56 | C6: PN | D6: COLUMBIANATIONAL REAL ESTATE FINANCE, LL | E6: 3617XHQ56_000000003411314 | F6: 202603 | G6: 5.73 | H6: 4785391.6 | I6: 420 | J6: 20250501 | K6: 20600601 | M6: 20350701 | N6: 10 | O6: 207/223(F) | T6: PA | U6: 42 | V6: 490.5 | W6: 10 | X6: 2025 | Y6: -9 | Z6: 10 | AA6: =IF(ISNUMBER(W6),W6,IFERROR(MAX(0,(VALUE(LEFT(F6,4))-VALUE(LEFT(TEXT(J6,"00000000"),4)))*12+(VALUE(MID(F6,5,2))-VALUE(MID(TEXT(J6,"00000000"),5,2)))),"")) | AB6: =IFERROR((VALUE(LEFT(TEXT(K6,"00000000"),4))-VALUE(LEFT(F6,4)))*12+(VALUE(MID(TEXT(K6,"00000000"),5,2))-VALUE(MID(F6,5,2))),"") | AC6: =IF(OR(L6="",NOT(ISNUMBER(L6))),0,MAX(0,MIN(60,(VALUE(LEFT(F6,4))-VALUE(LEFT(TEXT(L6,"00000000"),4)))*12+(VALUE(MID(F6,5,2))-VALUE(MID(TEXT(L6,"00000000"),5,2)))))) | AD6: =IF(OR(L6="",NOT(ISNUMBER(L6))),0,IF(VALUE(F6)<VALUE(LEFT(TEXT(L6,"00000000"),6)),1,0)) | AE6: =IF(OR(M6="",NOT(ISNUMBER(M6))),0,IF(VALUE(F6)<VALUE(LEFT(TEXT(M6,"00000000"),6)),1,0)) | AF6: =IF(AND(AD6=0,AE6=0),1,0) | AG6: =IF(ISNUMBER(X6),X6,IFERROR(VALUE(LEFT(TEXT(J6,"00000000"),4)),"")) | AH6: =IFERROR(XLOOKUP(AG6,Vintage_Rates!$A$2:$A$1000,Vintage_Rates!$B$2:$B$1000,""),"") | AI6: =IF(ISNUMBER(Y6),Y6,IFERROR((G6-AH6)*100,"")) | AJ6: =IF(ISNUMBER(V6),V6,IFERROR(XLOOKUP(VALUE(F6),PLC_Rates!$A$2:$A$1000,PLC_Rates!$B$2:$B$1000,""),"")) | AK6: =IF(ISNUMBER(Z6),Z6,IF(AE6=0,0,MAX(0,MIN(10,((VALUE(LEFT(TEXT(M6,"00000000"),4))-VALUE(LEFT(F6,4)))*12+(VALUE(MID(TEXT(M6,"00000000"),5,2))-VALUE(MID(F6,5,2))))/12)))) | AL6: =IFERROR(G6*100-AJ6,"") | AM6: =IFERROR(G6*100-(AJ6+(1+AK6)*12.5),"") | AN6: =IFERROR(MIN(H6/1000000,100),"") | AO6: =IFERROR(INDEX(FHA_Lookup!$B$2:$B$11,MATCH(TRUE,ISNUMBER(SEARCH(FHA_Lookup!$A$2:$A$11,UPPER(SUBSTITUTE(O6," ","")))),0)),"OTHER") | AP6: =IFERROR(INDEX(FHA_Lookup!$C$2:$C$11,MATCH(TRUE,ISNUMBER(SEARCH(FHA_Lookup!$A$2:$A$11,UPPER(SUBSTITUTE(O6," ","")))),0)),"OTHER") | AQ6: =IF(AP6="NC",1,0) | AR6: =IF(UPPER(TRIM(P6))="AFF",1,0) | AS6: =IF(UPPER(TRIM(P6))="BAF",1,0) | AT6: =IF(UPPER(TRIM(P6))="MKT",1,0) | AU6: =IF(AO6="221d4",1,0) | AV6: =IF(AO6="223a7",1,0) | AW6: =IF(AO6="232",1,0) | AX6: =IF(AO6="538",1,0) | AY6: =IF(AO6="241",1,0) | AZ6: =IF(AO6="220",1,0) | BA6: =IF(AO6="OTHER",1,0) | BB6: =IF(UPPER(TRIM(C6))="LM",1,0) | BC6: =IF(UPPER(TRIM(C6))="PN",1,0) | BD6: =IF(UPPER(TRIM(C6))="LS",1,0) | BE6: =IF(UPPER(TRIM(C6))="RX",1,0) | BF6: =IFERROR((Parameters!$C$6*AM6+Parameters!$C$7*MAX(AM6-(-150),0)+Parameters!$C$8*MAX(AM6-(-50),0)+Parameters!$C$9*MAX(AM6-(0),0)+Parameters!$C$10*MAX(AM6-(50),0)+Parameters!$C$11*MAX(AM6-(100),0)+Parameters!$C$12*MAX(AM6-(150),0)+Parameters!$C$13*MAX(AM6-(250),0)),0) | BG6: =IFERROR((Parameters!$C$14*AA6+Parameters!$C$15*MAX(AA6-(12),0)+Parameters!$C$16*MAX(AA6-(36),0)+Parameters!$C$17*MAX(AA6-(60),0)+Parameters!$C$18*MAX(AA6-(84),0)+Parameters!$C$19*MAX(AA6-(120),0)+Parameters!$C$20*MAX(AA6-(180),0)),0) | BH6: =IFERROR((Parameters!$C$21*AK6+Parameters!$C$22*MAX(AK6-(0),0)+Parameters!$C$23*MAX(AK6-(2),0)+Parameters!$C$24*MAX(AK6-(5),0)+Parameters!$C$25*MAX(AK6-(8),0)),0) | BI6: =IFERROR((Parameters!$C$26*AI6+Parameters!$C$27*MAX(AI6-(-100),0)+Parameters!$C$28*MAX(AI6-(-25),0)+Parameters!$C$29*MAX(AI6-(25),0)+Parameters!$C$30*MAX(AI6-(100),0)),0) | BJ6: =IFERROR((Parameters!$C$31*AN6+Parameters!$C$32*MAX(AN6-(2),0)+Parameters!$C$33*MAX(AN6-(10),0)+Parameters!$C$34*MAX(AN6-(25),0)),0) | BK6: =IFERROR((Parameters!$C$35*AB6+Parameters!$C$36*MAX(AB6-(12),0)+Parameters!$C$37*MAX(AB6-(24),0)+Parameters!$C$38*MAX(AB6-(60),0)),0) | BL6: =IFERROR((Parameters!$C$39*AC6+Parameters!$C$40*MAX(AC6-(6),0)+Parameters!$C$41*MAX(AC6-(12),0)+Parameters!$C$42*MAX(AC6-(24),0)),0) | BM6: =IFERROR(Parameters!$C$43*(MAX(AM6,0)*MIN(MAX(AK6,0),10))/100,0) | BN6: =Parameters!$C$44*AE6 | BO6: =Parameters!$C$45*AU6 + Parameters!$C$46*AV6 + Parameters!$C$47*AW6 + Parameters!$C$48*AX6 + Parameters!$C$49*AY6 + Parameters!$C$50*AZ6 + Parameters!$C$51*BA6 | BP6: =Parameters!$C$52*AQ6 | BQ6: =Parameters!$C$53*AR6+Parameters!$C$54*AS6+Parameters!$C$55*AT6 | BR6: =Parameters!$C$56*BB6+Parameters!$C$57*BC6+Parameters!$C$58*BD6+Parameters!$C$59*BE6 | BS6: =Parameters!$B$2 | BT6: =BS6+BF6 + BG6 + BH6 + BI6 + BJ6 + BK6 + BL6 + BM6 + BN6 + BO6 + BP6 + BQ6 + BR6 | BU6: =IF(AD6=1,0,1/(1+EXP(-BT6))*Parameters!$B$3) | BV6: =(1-(1-BU6)^12)*100 | BW6: =IF(AD6=1,0,(1-(1-1/(1+EXP(-Parameters!$B$2)))^12)*100) | BX6: =IF(AD6=1,0,BV6-(1-(1-(1/(1+EXP(-(BT6-BF6)))*Parameters!$B$3))^12)*100) | BY6: =IF(AD6=1,0,BV6-(1-(1-(1/(1+EXP(-(BT6-BG6)))*Parameters!$B$3))^12)*100) | BZ6: =IF(AD6=1,0,BV6-(1-(1-(1/(1+EXP(-(BT6-BH6)))*Parameters!$B$3))^12)*100) | CA6: =IF(AD6=1,0,BV6-(1-(1-(1/(1+EXP(-(BT6-BI6)))*Parameters!$B$3))^12)*100) | CB6: =IF(AD6=1,0,BV6-(1-(1-(1/(1+EXP(-(BT6-BJ6)))*Parameters!$B$3))^12)*100) | CC6: =IF(AD6=1,0,BV6-(1-(1-(1/(1+EXP(-(BT6-BK6)))*Parameters!$B$3))^12)*100) | CD6: =IF(AD6=1,0,BV6-(1-(1-(1/(1+EXP(-(BT6-BL6)))*Parameters!$B$3))^12)*100) | CE6: =IF(AD6=1,0,BV6-(1-(1-(1/(1+EXP(-(BT6-BM6)))*Parameters!$B$3))^12)*100) | CF6: =IF(AD6=1,0,BV6-(1-(1-(1/(1+EXP(-(BT6-BN6)))*Parameters!$B$3))^12)*100) | CG6: =IF(AD6=1,0,BV6-(1-(1-(1/(1+EXP(-(BT6-BO6)))*Parameters!$B$3))^12)*100) | CH6: =IF(AD6=1,0,BV6-(1-(1-(1/(1+EXP(-(BT6-BP6)))*Parameters!$B$3))^12)*100) | CI6: =IF(AD6=1,0,BV6-(1-(1-(1/(1+EXP(-(BT6-BQ6)))*Parameters!$B$3))^12)*100) | CJ6: =IF(AD6=1,0,BV6-(1-(1-(1/(1+EXP(-(BT6-BR6)))*Parameters!$B$3))^12)*100)
A7: GNR_2024_NEW | B7: 3618L6QB8 | C7: PN | D7: KEYBANK NATIONAL ASSOCIATION | E7: 3618L6QB8_000000005322284 | F7: 202603 | G7: 5.4 | H7: 21113919 | I7: 420 | J7: 20250901 | K7: 20601001 | M7: 20351031 | N7: 10 | O7: 232/223(F) | T7: NC | U7: 40 | V7: 490.5 | W7: 6 | X7: 2025 | Y7: -42 | Z7: 10 | AA7: =IF(ISNUMBER(W7),W7,IFERROR(MAX(0,(VALUE(LEFT(F7,4))-VALUE(LEFT(TEXT(J7,"00000000"),4)))*12+(VALUE(MID(F7,5,2))-VALUE(MID(TEXT(J7,"00000000"),5,2)))),"")) | AB7: =IFERROR((VALUE(LEFT(TEXT(K7,"00000000"),4))-VALUE(LEFT(F7,4)))*12+(VALUE(MID(TEXT(K7,"00000000"),5,2))-VALUE(MID(F7,5,2))),"") | AC7: =IF(OR(L7="",NOT(ISNUMBER(L7))),0,MAX(0,MIN(60,(VALUE(LEFT(F7,4))-VALUE(LEFT(TEXT(L7,"00000000"),4)))*12+(VALUE(MID(F7,5,2))-VALUE(MID(TEXT(L7,"00000000"),5,2)))))) | AD7: =IF(OR(L7="",NOT(ISNUMBER(L7))),0,IF(VALUE(F7)<VALUE(LEFT(TEXT(L7,"00000000"),6)),1,0)) | AE7: =IF(OR(M7="",NOT(ISNUMBER(M7))),0,IF(VALUE(F7)<VALUE(LEFT(TEXT(M7,"00000000"),6)),1,0)) | AF7: =IF(AND(AD7=0,AE7=0),1,0) | AG7: =IF(ISNUMBER(X7),X7,IFERROR(VALUE(LEFT(TEXT(J7,"00000000"),4)),"")) | AH7: =IFERROR(XLOOKUP(AG7,Vintage_Rates!$A$2:$A$1000,Vintage_Rates!$B$2:$B$1000,""),"") | AI7: =IF(ISNUMBER(Y7),Y7,IFERROR((G7-AH7)*100,"")) | AJ7: =IF(ISNUMBER(V7),V7,IFERROR(XLOOKUP(VALUE(F7),PLC_Rates!$A$2:$A$1000,PLC_Rates!$B$2:$B$1000,""),"")) | AK7: =IF(ISNUMBER(Z7),Z7,IF(AE7=0,0,MAX(0,MIN(10,((VALUE(LEFT(TEXT(M7,"00000000"),4))-VALUE(LEFT(F7,4)))*12+(VALUE(MID(TEXT(M7,"00000000"),5,2))-VALUE(MID(F7,5,2))))/12)))) | AL7: =IFERROR(G7*100-AJ7,"") | AM7: =IFERROR(G7*100-(AJ7+(1+AK7)*12.5),"") | AN7: =IFERROR(MIN(H7/1000000,100),"") | AO7: =IFERROR(INDEX(FHA_Lookup!$B$2:$B$11,MATCH(TRUE,ISNUMBER(SEARCH(FHA_Lookup!$A$2:$A$11,UPPER(SUBSTITUTE(O7," ","")))),0)),"OTHER") | AP7: =IFERROR(INDEX(FHA_Lookup!$C$2:$C$11,MATCH(TRUE,ISNUMBER(SEARCH(FHA_Lookup!$A$2:$A$11,UPPER(SUBSTITUTE(O7," ","")))),0)),"OTHER") | AQ7: =IF(AP7="NC",1,0) | AR7: =IF(UPPER(TRIM(P7))="AFF",1,0) | AS7: =IF(UPPER(TRIM(P7))="BAF",1,0) | AT7: =IF(UPPER(TRIM(P7))="MKT",1,0) | AU7: =IF(AO7="221d4",1,0) | AV7: =IF(AO7="223a7",1,0) | AW7: =IF(AO7="232",1,0) | AX7: =IF(AO7="538",1,0) | AY7: =IF(AO7="241",1,0) | AZ7: =IF(AO7="220",1,0) | BA7: =IF(AO7="OTHER",1,0) | BB7: =IF(UPPER(TRIM(C7))="LM",1,0) | BC7: =IF(UPPER(TRIM(C7))="PN",1,0) | BD7: =IF(UPPER(TRIM(C7))="LS",1,0) | BE7: =IF(UPPER(TRIM(C7))="RX",1,0) | BF7: =IFERROR((Parameters!$C$6*AM7+Parameters!$C$7*MAX(AM7-(-150),0)+Parameters!$C$8*MAX(AM7-(-50),0)+Parameters!$C$9*MAX(AM7-(0),0)+Parameters!$C$10*MAX(AM7-(50),0)+Parameters!$C$11*MAX(AM7-(100),0)+Parameters!$C$12*MAX(AM7-(150),0)+Parameters!$C$13*MAX(AM7-(250),0)),0) | BG7: =IFERROR((Parameters!$C$14*AA7+Parameters!$C$15*MAX(AA7-(12),0)+Parameters!$C$16*MAX(AA7-(36),0)+Parameters!$C$17*MAX(AA7-(60),0)+Parameters!$C$18*MAX(AA7-(84),0)+Parameters!$C$19*MAX(AA7-(120),0)+Parameters!$C$20*MAX(AA7-(180),0)),0) | BH7: =IFERROR((Parameters!$C$21*AK7+Parameters!$C$22*MAX(AK7-(0),0)+Parameters!$C$23*MAX(AK7-(2),0)+Parameters!$C$24*MAX(AK7-(5),0)+Parameters!$C$25*MAX(AK7-(8),0)),0) | BI7: =IFERROR((Parameters!$C$26*AI7+Parameters!$C$27*MAX(AI7-(-100),0)+Parameters!$C$28*MAX(AI7-(-25),0)+Parameters!$C$29*MAX(AI7-(25),0)+Parameters!$C$30*MAX(AI7-(100),0)),0) | BJ7: =IFERROR((Parameters!$C$31*AN7+Parameters!$C$32*MAX(AN7-(2),0)+Parameters!$C$33*MAX(AN7-(10),0)+Parameters!$C$34*MAX(AN7-(25),0)),0) | BK7: =IFERROR((Parameters!$C$35*AB7+Parameters!$C$36*MAX(AB7-(12),0)+Parameters!$C$37*MAX(AB7-(24),0)+Parameters!$C$38*MAX(AB7-(60),0)),0) | BL7: =IFERROR((Parameters!$C$39*AC7+Parameters!$C$40*MAX(AC7-(6),0)+Parameters!$C$41*MAX(AC7-(12),0)+Parameters!$C$42*MAX(AC7-(24),0)),0) | BM7: =IFERROR(Parameters!$C$43*(MAX(AM7,0)*MIN(MAX(AK7,0),10))/100,0) | BN7: =Parameters!$C$44*AE7 | BO7: =Parameters!$C$45*AU7 + Parameters!$C$46*AV7 + Parameters!$C$47*AW7 + Parameters!$C$48*AX7 + Parameters!$C$49*AY7 + Parameters!$C$50*AZ7 + Parameters!$C$51*BA7 | BP7: =Parameters!$C$52*AQ7 | BQ7: =Parameters!$C$53*AR7+Parameters!$C$54*AS7+Parameters!$C$55*AT7 | BR7: =Parameters!$C$56*BB7+Parameters!$C$57*BC7+Parameters!$C$58*BD7+Parameters!$C$59*BE7 | BS7: =Parameters!$B$2 | BT7: =BS7+BF7 + BG7 + BH7 + BI7 + BJ7 + BK7 + BL7 + BM7 + BN7 + BO7 + BP7 + BQ7 + BR7 | BU7: =IF(AD7=1,0,1/(1+EXP(-BT7))*Parameters!$B$3) | BV7: =(1-(1-BU7)^12)*100 | BW7: =IF(AD7=1,0,(1-(1-1/(1+EXP(-Parameters!$B$2)))^12)*100) | BX7: =IF(AD7=1,0,BV7-(1-(1-(1/(1+EXP(-(BT7-BF7)))*Parameters!$B$3))^12)*100) | BY7: =IF(AD7=1,0,BV7-(1-(1-(1/(1+EXP(-(BT7-BG7)))*Parameters!$B$3))^12)*100) | BZ7: =IF(AD7=1,0,BV7-(1-(1-(1/(1+EXP(-(BT7-BH7)))*Parameters!$B$3))^12)*100) | CA7: =IF(AD7=1,0,BV7-(1-(1-(1/(1+EXP(-(BT7-BI7)))*Parameters!$B$3))^12)*100) | CB7: =IF(AD7=1,0,BV7-(1-(1-(1/(1+EXP(-(BT7-BJ7)))*Parameters!$B$3))^12)*100) | CC7: =IF(AD7=1,0,BV7-(1-(1-(1/(1+EXP(-(BT7-BK7)))*Parameters!$B$3))^12)*100) | CD7: =IF(AD7=1,0,BV7-(1-(1-(1/(1+EXP(-(BT7-BL7)))*Parameters!$B$3))^12)*100) | CE7: =IF(AD7=1,0,BV7-(1-(1-(1/(1+EXP(-(BT7-BM7)))*Parameters!$B$3))^12)*100) | CF7: =IF(AD7=1,0,BV7-(1-(1-(1/(1+EXP(-(BT7-BN7)))*Parameters!$B$3))^12)*100) | CG7: =IF(AD7=1,0,BV7-(1-(1-(1/(1+EXP(-(BT7-BO7)))*Parameters!$B$3))^12)*100) | CH7: =IF(AD7=1,0,BV7-(1-(1-(1/(1+EXP(-(BT7-BP7)))*Parameters!$B$3))^12)*100) | CI7: =IF(AD7=1,0,BV7-(1-(1-(1/(1+EXP(-(BT7-BQ7)))*Parameters!$B$3))^12)*100) | CJ7: =IF(AD7=1,0,BV7-(1-(1-(1/(1+EXP(-(BT7-BR7)))*Parameters!$B$3))^12)*100)
A8: GNR_2024_NEW | B8: 3618HGKV3 | C8: PN | D8: WELLS FARGO BANK, N.A. | E8: 3618HGKV3_000000010111361 | F8: 202603 | G8: 5.92 | H8: 20435174 | I8: 420 | J8: 20250701 | K8: 20600801 | L8: 20250901 | M8: 20350901 | N8: 10 | O8: 207/223(f) | T8: CO | U8: 120 | V8: 490.5 | W8: 8 | X8: 2025 | Y8: 10 | Z8: 10 | AA8: =IF(ISNUMBER(W8),W8,IFERROR(MAX(0,(VALUE(LEFT(F8,4))-VALUE(LEFT(TEXT(J8,"00000000"),4)))*12+(VALUE(MID(F8,5,2))-VALUE(MID(TEXT(J8,"00000000"),5,2)))),"")) | AB8: =IFERROR((VALUE(LEFT(TEXT(K8,"00000000"),4))-VALUE(LEFT(F8,4)))*12+(VALUE(MID(TEXT(K8,"00000000"),5,2))-VALUE(MID(F8,5,2))),"") | AC8: =IF(OR(L8="",NOT(ISNUMBER(L8))),0,MAX(0,MIN(60,(VALUE(LEFT(F8,4))-VALUE(LEFT(TEXT(L8,"00000000"),4)))*12+(VALUE(MID(F8,5,2))-VALUE(MID(TEXT(L8,"00000000"),5,2)))))) | AD8: =IF(OR(L8="",NOT(ISNUMBER(L8))),0,IF(VALUE(F8)<VALUE(LEFT(TEXT(L8,"00000000"),6)),1,0)) | AE8: =IF(OR(M8="",NOT(ISNUMBER(M8))),0,IF(VALUE(F8)<VALUE(LEFT(TEXT(M8,"00000000"),6)),1,0)) | AF8: =IF(AND(AD8=0,AE8=0),1,0) | AG8: =IF(ISNUMBER(X8),X8,IFERROR(VALUE(LEFT(TEXT(J8,"00000000"),4)),"")) | AH8: =IFERROR(XLOOKUP(AG8,Vintage_Rates!$A$2:$A$1000,Vintage_Rates!$B$2:$B$1000,""),"") | AI8: =IF(ISNUMBER(Y8),Y8,IFERROR((G8-AH8)*100,"")) | AJ8: =IF(ISNUMBER(V8),V8,IFERROR(XLOOKUP(VALUE(F8),PLC_Rates!$A$2:$A$1000,PLC_Rates!$B$2:$B$1000,""),"")) | AK8: =IF(ISNUMBER(Z8),Z8,IF(AE8=0,0,MAX(0,MIN(10,((VALUE(LEFT(TEXT(M8,"00000000"),4))-VALUE(LEFT(F8,4)))*12+(VALUE(MID(TEXT(M8,"00000000"),5,2))-VALUE(MID(F8,5,2))))/12)))) | AL8: =IFERROR(G8*100-AJ8,"") | AM8: =IFERROR(G8*100-(AJ8+(1+AK8)*12.5),"") | AN8: =IFERROR(MIN(H8/1000000,100),"") | AO8: =IFERROR(INDEX(FHA_Lookup!$B$2:$B$11,MATCH(TRUE,ISNUMBER(SEARCH(FHA_Lookup!$A$2:$A$11,UPPER(SUBSTITUTE(O8," ","")))),0)),"OTHER") | AP8: =IFERROR(INDEX(FHA_Lookup!$C$2:$C$11,MATCH(TRUE,ISNUMBER(SEARCH(FHA_Lookup!$A$2:$A$11,UPPER(SUBSTITUTE(O8," ","")))),0)),"OTHER") | AQ8: =IF(AP8="NC",1,0) | AR8: =IF(UPPER(TRIM(P8))="AFF",1,0) | AS8: =IF(UPPER(TRIM(P8))="BAF",1,0) | AT8: =IF(UPPER(TRIM(P8))="MKT",1,0) | AU8: =IF(AO8="221d4",1,0) | AV8: =IF(AO8="223a7",1,0) | AW8: =IF(AO8="232",1,0) | AX8: =IF(AO8="538",1,0) | AY8: =IF(AO8="241",1,0) | AZ8: =IF(AO8="220",1,0) | BA8: =IF(AO8="OTHER",1,0) | BB8: =IF(UPPER(TRIM(C8))="LM",1,0) | BC8: =IF(UPPER(TRIM(C8))="PN",1,0) | BD8: =IF(UPPER(TRIM(C8))="LS",1,0) | BE8: =IF(UPPER(TRIM(C8))="RX",1,0) | BF8: =IFERROR((Parameters!$C$6*AM8+Parameters!$C$7*MAX(AM8-(-150),0)+Parameters!$C$8*MAX(AM8-(-50),0)+Parameters!$C$9*MAX(AM8-(0),0)+Parameters!$C$10*MAX(AM8-(50),0)+Parameters!$C$11*MAX(AM8-(100),0)+Parameters!$C$12*MAX(AM8-(150),0)+Parameters!$C$13*MAX(AM8-(250),0)),0) | BG8: =IFERROR((Parameters!$C$14*AA8+Parameters!$C$15*MAX(AA8-(12),0)+Parameters!$C$16*MAX(AA8-(36),0)+Parameters!$C$17*MAX(AA8-(60),0)+Parameters!$C$18*MAX(AA8-(84),0)+Parameters!$C$19*MAX(AA8-(120),0)+Parameters!$C$20*MAX(AA8-(180),0)),0) | BH8: =IFERROR((Parameters!$C$21*AK8+Parameters!$C$22*MAX(AK8-(0),0)+Parameters!$C$23*MAX(AK8-(2),0)+Parameters!$C$24*MAX(AK8-(5),0)+Parameters!$C$25*MAX(AK8-(8),0)),0) | BI8: =IFERROR((Parameters!$C$26*AI8+Parameters!$C$27*MAX(AI8-(-100),0)+Parameters!$C$28*MAX(AI8-(-25),0)+Parameters!$C$29*MAX(AI8-(25),0)+Parameters!$C$30*MAX(AI8-(100),0)),0) | BJ8: =IFERROR((Parameters!$C$31*AN8+Parameters!$C$32*MAX(AN8-(2),0)+Parameters!$C$33*MAX(AN8-(10),0)+Parameters!$C$34*MAX(AN8-(25),0)),0) | BK8: =IFERROR((Parameters!$C$35*AB8+Parameters!$C$36*MAX(AB8-(12),0)+Parameters!$C$37*MAX(AB8-(24),0)+Parameters!$C$38*MAX(AB8-(60),0)),0) | BL8: =IFERROR((Parameters!$C$39*AC8+Parameters!$C$40*MAX(AC8-(6),0)+Parameters!$C$41*MAX(AC8-(12),0)+Parameters!$C$42*MAX(AC8-(24),0)),0) | BM8: =IFERROR(Parameters!$C$43*(MAX(AM8,0)*MIN(MAX(AK8,0),10))/100,0) | BN8: =Parameters!$C$44*AE8 | BO8: =Parameters!$C$45*AU8 + Parameters!$C$46*AV8 + Parameters!$C$47*AW8 + Parameters!$C$48*AX8 + Parameters!$C$49*AY8 + Parameters!$C$50*AZ8 + Parameters!$C$51*BA8 | BP8: =Parameters!$C$52*AQ8 | BQ8: =Parameters!$C$53*AR8+Parameters!$C$54*AS8+Parameters!$C$55*AT8 | BR8: =Parameters!$C$56*BB8+Parameters!$C$57*BC8+Parameters!$C$58*BD8+Parameters!$C$59*BE8 | BS8: =Parameters!$B$2 | BT8: =BS8+BF8 + BG8 + BH8 + BI8 + BJ8 + BK8 + BL8 + BM8 + BN8 + BO8 + BP8 + BQ8 + BR8 | BU8: =IF(AD8=1,0,1/(1+EXP(-BT8))*Parameters!$B$3) | BV8: =(1-(1-BU8)^12)*100 | BW8: =IF(AD8=1,0,(1-(1-1/(1+EXP(-Parameters!$B$2)))^12)*100) | BX8: =IF(AD8=1,0,BV8-(1-(1-(1/(1+EXP(-(BT8-BF8)))*Parameters!$B$3))^12)*100) | BY8: =IF(AD8=1,0,BV8-(1-(1-(1/(1+EXP(-(BT8-BG8)))*Parameters!$B$3))^12)*100) | BZ8: =IF(AD8=1,0,BV8-(1-(1-(1/(1+EXP(-(BT8-BH8)))*Parameters!$B$3))^12)*100) | CA8: =IF(AD8=1,0,BV8-(1-(1-(1/(1+EXP(-(BT8-BI8)))*Parameters!$B$3))^12)*100) | CB8: =IF(AD8=1,0,BV8-(1-(1-(1/(1+EXP(-(BT8-BJ8)))*Parameters!$B$3))^12)*100) | CC8: =IF(AD8=1,0,BV8-(1-(1-(1/(1+EXP(-(BT8-BK8)))*Parameters!$B$3))^12)*100) | CD8: =IF(AD8=1,0,BV8-(1-(1-(1/(1+EXP(-(BT8-BL8)))*Parameters!$B$3))^12)*100) | CE8: =IF(AD8=1,0,BV8-(1-(1-(1/(1+EXP(-(BT8-BM8)))*Parameters!$B$3))^12)*100) | CF8: =IF(AD8=1,0,BV8-(1-(1-(1/(1+EXP(-(BT8-BN8)))*Parameters!$B$3))^12)*100) | CG8: =IF(AD8=1,0,BV8-(1-(1-(1/(1+EXP(-(BT8-BO8)))*Parameters!$B$3))^12)*100) | CH8: =IF(AD8=1,0,BV8-(1-(1-(1/(1+EXP(-(BT8-BP8)))*Parameters!$B$3))^12)*100) | CI8: =IF(AD8=1,0,BV8-(1-(1-(1/(1+EXP(-(BT8-BQ8)))*Parameters!$B$3))^12)*100) | CJ8: =IF(AD8=1,0,BV8-(1-(1-(1/(1+EXP(-(BT8-BR8)))*Parameters!$B$3))^12)*100)
A9: GNR_2024_NEW | B9: 3618GTXQ3 | C9: PN | D9: BERKADIA COMMERCIAL MORTGAGE, LLC | E9: 3618GTXQ3_000000006311195 | F9: 202603 | G9: 5.07 | H9: 21410853 | I9: 420 | J9: 20240625 | K9: 20590901 | M9: 20341001 | N9: 10 | O9: 207/223(F) | P9: MKT | T9: FL | U9: 124 | V9: 490.5 | W9: 21 | X9: 2024 | Y9: -71 | Z9: 10 | AA9: =IF(ISNUMBER(W9),W9,IFERROR(MAX(0,(VALUE(LEFT(F9,4))-VALUE(LEFT(TEXT(J9,"00000000"),4)))*12+(VALUE(MID(F9,5,2))-VALUE(MID(TEXT(J9,"00000000"),5,2)))),"")) | AB9: =IFERROR((VALUE(LEFT(TEXT(K9,"00000000"),4))-VALUE(LEFT(F9,4)))*12+(VALUE(MID(TEXT(K9,"00000000"),5,2))-VALUE(MID(F9,5,2))),"") | AC9: =IF(OR(L9="",NOT(ISNUMBER(L9))),0,MAX(0,MIN(60,(VALUE(LEFT(F9,4))-VALUE(LEFT(TEXT(L9,"00000000"),4)))*12+(VALUE(MID(F9,5,2))-VALUE(MID(TEXT(L9,"00000000"),5,2)))))) | AD9: =IF(OR(L9="",NOT(ISNUMBER(L9))),0,IF(VALUE(F9)<VALUE(LEFT(TEXT(L9,"00000000"),6)),1,0)) | AE9: =IF(OR(M9="",NOT(ISNUMBER(M9))),0,IF(VALUE(F9)<VALUE(LEFT(TEXT(M9,"00000000"),6)),1,0)) | AF9: =IF(AND(AD9=0,AE9=0),1,0) | AG9: =IF(ISNUMBER(X9),X9,IFERROR(VALUE(LEFT(TEXT(J9,"00000000"),4)),"")) | AH9: =IFERROR(XLOOKUP(AG9,Vintage_Rates!$A$2:$A$1000,Vintage_Rates!$B$2:$B$1000,""),"") | AI9: =IF(ISNUMBER(Y9),Y9,IFERROR((G9-AH9)*100,"")) | AJ9: =IF(ISNUMBER(V9),V9,IFERROR(XLOOKUP(VALUE(F9),PLC_Rates!$A$2:$A$1000,PLC_Rates!$B$2:$B$1000,""),"")) | AK9: =IF(ISNUMBER(Z9),Z9,IF(AE9=0,0,MAX(0,MIN(10,((VALUE(LEFT(TEXT(M9,"00000000"),4))-VALUE(LEFT(F9,4)))*12+(VALUE(MID(TEXT(M9,"00000000"),5,2))-VALUE(MID(F9,5,2))))/12)))) | AL9: =IFERROR(G9*100-AJ9,"") | AM9: =IFERROR(G9*100-(AJ9+(1+AK9)*12.5),"") | AN9: =IFERROR(MIN(H9/1000000,100),"") | AO9: =IFERROR(INDEX(FHA_Lookup!$B$2:$B$11,MATCH(TRUE,ISNUMBER(SEARCH(FHA_Lookup!$A$2:$A$11,UPPER(SUBSTITUTE(O9," ","")))),0)),"OTHER") | AP9: =IFERROR(INDEX(FHA_Lookup!$C$2:$C$11,MATCH(TRUE,ISNUMBER(SEARCH(FHA_Lookup!$A$2:$A$11,UPPER(SUBSTITUTE(O9," ","")))),0)),"OTHER") | AQ9: =IF(AP9="NC",1,0) | AR9: =IF(UPPER(TRIM(P9))="AFF",1,0) | AS9: =IF(UPPER(TRIM(P9))="BAF",1,0) | AT9: =IF(UPPER(TRIM(P9))="MKT",1,0) | AU9: =IF(AO9="221d4",1,0) | AV9: =IF(AO9="223a7",1,0) | AW9: =IF(AO9="232",1,0) | AX9: =IF(AO9="538",1,0) | AY9: =IF(AO9="241",1,0) | AZ9: =IF(AO9="220",1,0) | BA9: =IF(AO9="OTHER",1,0) | BB9: =IF(UPPER(TRIM(C9))="LM",1,0) | BC9: =IF(UPPER(TRIM(C9))="PN",1,0) | BD9: =IF(UPPER(TRIM(C9))="LS",1,0) | BE9: =IF(UPPER(TRIM(C9))="RX",1,0) | BF9: =IFERROR((Parameters!$C$6*AM9+Parameters!$C$7*MAX(AM9-(-150),0)+Parameters!$C$8*MAX(AM9-(-50),0)+Parameters!$C$9*MAX(AM9-(0),0)+Parameters!$C$10*MAX(AM9-(50),0)+Parameters!$C$11*MAX(AM9-(100),0)+Parameters!$C$12*MAX(AM9-(150),0)+Parameters!$C$13*MAX(AM9-(250),0)),0) | BG9: =IFERROR((Parameters!$C$14*AA9+Parameters!$C$15*MAX(AA9-(12),0)+Parameters!$C$16*MAX(AA9-(36),0)+Parameters!$C$17*MAX(AA9-(60),0)+Parameters!$C$18*MAX(AA9-(84),0)+Parameters!$C$19*MAX(AA9-(120),0)+Parameters!$C$20*MAX(AA9-(180),0)),0) | BH9: =IFERROR((Parameters!$C$21*AK9+Parameters!$C$22*MAX(AK9-(0),0)+Parameters!$C$23*MAX(AK9-(2),0)+Parameters!$C$24*MAX(AK9-(5),0)+Parameters!$C$25*MAX(AK9-(8),0)),0) | BI9: =IFERROR((Parameters!$C$26*AI9+Parameters!$C$27*MAX(AI9-(-100),0)+Parameters!$C$28*MAX(AI9-(-25),0)+Parameters!$C$29*MAX(AI9-(25),0)+Parameters!$C$30*MAX(AI9-(100),0)),0) | BJ9: =IFERROR((Parameters!$C$31*AN9+Parameters!$C$32*MAX(AN9-(2),0)+Parameters!$C$33*MAX(AN9-(10),0)+Parameters!$C$34*MAX(AN9-(25),0)),0) | BK9: =IFERROR((Parameters!$C$35*AB9+Parameters!$C$36*MAX(AB9-(12),0)+Parameters!$C$37*MAX(AB9-(24),0)+Parameters!$C$38*MAX(AB9-(60),0)),0) | BL9: =IFERROR((Parameters!$C$39*AC9+Parameters!$C$40*MAX(AC9-(6),0)+Parameters!$C$41*MAX(AC9-(12),0)+Parameters!$C$42*MAX(AC9-(24),0)),0) | BM9: =IFERROR(Parameters!$C$43*(MAX(AM9,0)*MIN(MAX(AK9,0),10))/100,0) | BN9: =Parameters!$C$44*AE9 | BO9: =Parameters!$C$45*AU9 + Parameters!$C$46*AV9 + Parameters!$C$47*AW9 + Parameters!$C$48*AX9 + Parameters!$C$49*AY9 + Parameters!$C$50*AZ9 + Parameters!$C$51*BA9 | BP9: =Parameters!$C$52*AQ9 | BQ9: =Parameters!$C$53*AR9+Parameters!$C$54*AS9+Parameters!$C$55*AT9 | BR9: =Parameters!$C$56*BB9+Parameters!$C$57*BC9+Parameters!$C$58*BD9+Parameters!$C$59*BE9 | BS9: =Parameters!$B$2 | BT9: =BS9+BF9 + BG9 + BH9 + BI9 + BJ9 + BK9 + BL9 + BM9 + BN9 + BO9 + BP9 + BQ9 + BR9 | BU9: =IF(AD9=1,0,1/(1+EXP(-BT9))*Parameters!$B$3) | BV9: =(1-(1-BU9)^12)*100 | BW9: =IF(AD9=1,0,(1-(1-1/(1+EXP(-Parameters!$B$2)))^12)*100) | BX9: =IF(AD9=1,0,BV9-(1-(1-(1/(1+EXP(-(BT9-BF9)))*Parameters!$B$3))^12)*100) | BY9: =IF(AD9=1,0,BV9-(1-(1-(1/(1+EXP(-(BT9-BG9)))*Parameters!$B$3))^12)*100) | BZ9: =IF(AD9=1,0,BV9-(1-(1-(1/(1+EXP(-(BT9-BH9)))*Parameters!$B$3))^12)*100) | CA9: =IF(AD9=1,0,BV9-(1-(1-(1/(1+EXP(-(BT9-BI9)))*Parameters!$B$3))^12)*100) | CB9: =IF(AD9=1,0,BV9-(1-(1-(1/(1+EXP(-(BT9-BJ9)))*Parameters!$B$3))^12)*100) | CC9: =IF(AD9=1,0,BV9-(1-(1-(1/(1+EXP(-(BT9-BK9)))*Parameters!$B$3))^12)*100) | CD9: =IF(AD9=1,0,BV9-(1-(1-(1/(1+EXP(-(BT9-BL9)))*Parameters!$B$3))^12)*100) | CE9: =IF(AD9=1,0,BV9-(1-(1-(1/(1+EXP(-(BT9-BM9)))*Parameters!$B$3))^12)*100) | CF9: =IF(AD9=1,0,BV9-(1-(1-(1/(1+EXP(-(BT9-BN9)))*Parameters!$B$3))^12)*100) | CG9: =IF(AD9=1,0,BV9-(1-(1-(1/(1+EXP(-(BT9-BO9)))*Parameters!$B$3))^12)*100) | CH9: =IF(AD9=1,0,BV9-(1-(1-(1/(1+EXP(-(BT9-BP9)))*Parameters!$B$3))^12)*100) | CI9: =IF(AD9=1,0,BV9-(1-(1-(1/(1+EXP(-(BT9-BQ9)))*Parameters!$B$3))^12)*100) | CJ9: =IF(AD9=1,0,BV9-(1-(1-(1/(1+EXP(-(BT9-BR9)))*Parameters!$B$3))^12)*100)
A10: GNR_2024_NEW | B10: 3618JS5S9 | C10: PN | D10: BERKADIA COMMERCIAL MORTGAGE, LLC | E10: 3618JS5S9_000000005422124 | F10: 202603 | G10: 5.88 | H10: 6297447.2 | I10: 360 | J10: 20250115 | K10: 20550401 | M10: 20350501 | N10: 10 | O10: 232/223(f) | T10: SC | U10: 60 | V10: 490.5 | W10: 14 | X10: 2025 | Y10: 6 | Z10: 0 | AA10: =IF(ISNUMBER(W10),W10,IFERROR(MAX(0,(VALUE(LEFT(F10,4))-VALUE(LEFT(TEXT(J10,"00000000"),4)))*12+(VALUE(MID(F10,5,2))-VALUE(MID(TEXT(J10,"00000000"),5,2)))),"")) | AB10: =IFERROR((VALUE(LEFT(TEXT(K10,"00000000"),4))-VALUE(LEFT(F10,4)))*12+(VALUE(MID(TEXT(K10,"00000000"),5,2))-VALUE(MID(F10,5,2))),"") | AC10: =IF(OR(L10="",NOT(ISNUMBER(L10))),0,MAX(0,MIN(60,(VALUE(LEFT(F10,4))-VALUE(LEFT(TEXT(L10,"00000000"),4)))*12+(VALUE(MID(F10,5,2))-VALUE(MID(TEXT(L10,"00000000"),5,2)))))) | AD10: =IF(OR(L10="",NOT(ISNUMBER(L10))),0,IF(VALUE(F10)<VALUE(LEFT(TEXT(L10,"00000000"),6)),1,0)) | AE10: =IF(OR(M10="",NOT(ISNUMBER(M10))),0,IF(VALUE(F10)<VALUE(LEFT(TEXT(M10,"00000000"),6)),1,0)) | AF10: =IF(AND(AD10=0,AE10=0),1,0) | AG10: =IF(ISNUMBER(X10),X10,IFERROR(VALUE(LEFT(TEXT(J10,"00000000"),4)),"")) | AH10: =IFERROR(XLOOKUP(AG10,Vintage_Rates!$A$2:$A$1000,Vintage_Rates!$B$2:$B$1000,""),"") | AI10: =IF(ISNUMBER(Y10),Y10,IFERROR((G10-AH10)*100,"")) | AJ10: =IF(ISNUMBER(V10),V10,IFERROR(XLOOKUP(VALUE(F10),PLC_Rates!$A$2:$A$1000,PLC_Rates!$B$2:$B$1000,""),"")) | AK10: =IF(ISNUMBER(Z10),Z10,IF(AE10=0,0,MAX(0,MIN(10,((VALUE(LEFT(TEXT(M10,"00000000"),4))-VALUE(LEFT(F10,4)))*12+(VALUE(MID(TEXT(M10,"00000000"),5,2))-VALUE(MID(F10,5,2))))/12)))) | AL10: =IFERROR(G10*100-AJ10,"") | AM10: =IFERROR(G10*100-(AJ10+(1+AK10)*12.5),"") | AN10: =IFERROR(MIN(H10/1000000,100),"") | AO10: =IFERROR(INDEX(FHA_Lookup!$B$2:$B$11,MATCH(TRUE,ISNUMBER(SEARCH(FHA_Lookup!$A$2:$A$11,UPPER(SUBSTITUTE(O10," ","")))),0)),"OTHER") | AP10: =IFERROR(INDEX(FHA_Lookup!$C$2:$C$11,MATCH(TRUE,ISNUMBER(SEARCH(FHA_Lookup!$A$2:$A$11,UPPER(SUBSTITUTE(O10," ","")))),0)),"OTHER") | AQ10: =IF(AP10="NC",1,0) | AR10: =IF(UPPER(TRIM(P10))="AFF",1,0) | AS10: =IF(UPPER(TRIM(P10))="BAF",1,0) | AT10: =IF(UPPER(TRIM(P10))="MKT",1,0) | AU10: =IF(AO10="221d4",1,0) | AV10: =IF(AO10="223a7",1,0) | AW10: =IF(AO10="232",1,0) | AX10: =IF(AO10="538",1,0) | AY10: =IF(AO10="241",1,0) | AZ10: =IF(AO10="220",1,0) | BA10: =IF(AO10="OTHER",1,0) | BB10: =IF(UPPER(TRIM(C10))="LM",1,0) | BC10: =IF(UPPER(TRIM(C10))="PN",1,0) | BD10: =IF(UPPER(TRIM(C10))="LS",1,0) | BE10: =IF(UPPER(TRIM(C10))="RX",1,0) | BF10: =IFERROR((Parameters!$C$6*AM10+Parameters!$C$7*MAX(AM10-(-150),0)+Parameters!$C$8*MAX(AM10-(-50),0)+Parameters!$C$9*MAX(AM10-(0),0)+Parameters!$C$10*MAX(AM10-(50),0)+Parameters!$C$11*MAX(AM10-(100),0)+Parameters!$C$12*MAX(AM10-(150),0)+Parameters!$C$13*MAX(AM10-(250),0)),0) | BG10: =IFERROR((Parameters!$C$14*AA10+Parameters!$C$15*MAX(AA10-(12),0)+Parameters!$C$16*MAX(AA10-(36),0)+Parameters!$C$17*MAX(AA10-(60),0)+Parameters!$C$18*MAX(AA10-(84),0)+Parameters!$C$19*MAX(AA10-(120),0)+Parameters!$C$20*MAX(AA10-(180),0)),0) | BH10: =IFERROR((Parameters!$C$21*AK10+Parameters!$C$22*MAX(AK10-(0),0)+Parameters!$C$23*MAX(AK10-(2),0)+Parameters!$C$24*MAX(AK10-(5),0)+Parameters!$C$25*MAX(AK10-(8),0)),0) | BI10: =IFERROR((Parameters!$C$26*AI10+Parameters!$C$27*MAX(AI10-(-100),0)+Parameters!$C$28*MAX(AI10-(-25),0)+Parameters!$C$29*MAX(AI10-(25),0)+Parameters!$C$30*MAX(AI10-(100),0)),0) | BJ10: =IFERROR((Parameters!$C$31*AN10+Parameters!$C$32*MAX(AN10-(2),0)+Parameters!$C$33*MAX(AN10-(10),0)+Parameters!$C$34*MAX(AN10-(25),0)),0) | BK10: =IFERROR((Parameters!$C$35*AB10+Parameters!$C$36*MAX(AB10-(12),0)+Parameters!$C$37*MAX(AB10-(24),0)+Parameters!$C$38*MAX(AB10-(60),0)),0) | BL10: =IFERROR((Parameters!$C$39*AC10+Parameters!$C$40*MAX(AC10-(6),0)+Parameters!$C$41*MAX(AC10-(12),0)+Parameters!$C$42*MAX(AC10-(24),0)),0) | BM10: =IFERROR(Parameters!$C$43*(MAX(AM10,0)*MIN(MAX(AK10,0),10))/100,0) | BN10: =Parameters!$C$44*AE10 | BO10: =Parameters!$C$45*AU10 + Parameters!$C$46*AV10 + Parameters!$C$47*AW10 + Parameters!$C$48*AX10 + Parameters!$C$49*AY10 + Parameters!$C$50*AZ10 + Parameters!$C$51*BA10 | BP10: =Parameters!$C$52*AQ10 | BQ10: =Parameters!$C$53*AR10+Parameters!$C$54*AS10+Parameters!$C$55*AT10 | BR10: =Parameters!$C$56*BB10+Parameters!$C$57*BC10+Parameters!$C$58*BD10+Parameters!$C$59*BE10 | BS10: =Parameters!$B$2 | BT10: =BS10+BF10 + BG10 + BH10 + BI10 + BJ10 + BK10 + BL10 + BM10 + BN10 + BO10 + BP10 + BQ10 + BR10 | BU10: =IF(AD10=1,0,1/(1+EXP(-BT10))*Parameters!$B$3) | BV10: =(1-(1-BU10)^12)*100 | BW10: =IF(AD10=1,0,(1-(1-1/(1+EXP(-Parameters!$B$2)))^12)*100) | BX10: =IF(AD10=1,0,BV10-(1-(1-(1/(1+EXP(-(BT10-BF10)))*Parameters!$B$3))^12)*100) | BY10: =IF(AD10=1,0,BV10-(1-(1-(1/(1+EXP(-(BT10-BG10)))*Parameters!$B$3))^12)*100) | BZ10: =IF(AD10=1,0,BV10-(1-(1-(1/(1+EXP(-(BT10-BH10)))*Parameters!$B$3))^12)*100) | CA10: =IF(AD10=1,0,BV10-(1-(1-(1/(1+EXP(-(BT10-BI10)))*Parameters!$B$3))^12)*100) | CB10: =IF(AD10=1,0,BV10-(1-(1-(1/(1+EXP(-(BT10-BJ10)))*Parameters!$B$3))^12)*100) | CC10: =IF(AD10=1,0,BV10-(1-(1-(1/(1+EXP(-(BT10-BK10)))*Parameters!$B$3))^12)*100) | CD10: =IF(AD10=1,0,BV10-(1-(1-(1/(1+EXP(-(BT10-BL10)))*Parameters!$B$3))^12)*100) | CE10: =IF(AD10=1,0,BV10-(1-(1-(1/(1+EXP(-(BT10-BM10)))*Parameters!$B$3))^12)*100) | CF10: =IF(AD10=1,0,BV10-(1-(1-(1/(1+EXP(-(BT10-BN10)))*Parameters!$B$3))^12)*100) | CG10: =IF(AD10=1,0,BV10-(1-(1-(1/(1+EXP(-(BT10-BO10)))*Parameters!$B$3))^12)*100) | CH10: =IF(AD10=1,0,BV10-(1-(1-(1/(1+EXP(-(BT10-BP10)))*Parameters!$B$3))^12)*100) | CI10: =IF(AD10=1,0,BV10-(1-(1-(1/(1+EXP(-(BT10-BQ10)))*Parameters!$B$3))^12)*100) | CJ10: =IF(AD10=1,0,BV10-(1-(1-(1/(1+EXP(-(BT10-BR10)))*Parameters!$B$3))^12)*100)
A11: GNR_2024_NEW | B11: 3618AVAN6 | C11: PN | D11: GREYSTONE FUNDING COMPANY LLC | E11: 3618AVAN6_000000001211578 | F11: 202603 | G11: 5.42 | H11: 62488944 | I11: 420 | J11: 20230228 | K11: 20580301 | M11: 20330401 | N11: 10 | O11: 207/223(F) | P11: BAF | T11: NY | U11: 251 | V11: 490.5 | W11: 37 | X11: 2023 | Y11: -16.5 | Z11: 8 | AA11: =IF(ISNUMBER(W11),W11,IFERROR(MAX(0,(VALUE(LEFT(F11,4))-VALUE(LEFT(TEXT(J11,"00000000"),4)))*12+(VALUE(MID(F11,5,2))-VALUE(MID(TEXT(J11,"00000000"),5,2)))),"")) | AB11: =IFERROR((VALUE(LEFT(TEXT(K11,"00000000"),4))-VALUE(LEFT(F11,4)))*12+(VALUE(MID(TEXT(K11,"00000000"),5,2))-VALUE(MID(F11,5,2))),"") | AC11: =IF(OR(L11="",NOT(ISNUMBER(L11))),0,MAX(0,MIN(60,(VALUE(LEFT(F11,4))-VALUE(LEFT(TEXT(L11,"00000000"),4)))*12+(VALUE(MID(F11,5,2))-VALUE(MID(TEXT(L11,"00000000"),5,2)))))) | AD11: =IF(OR(L11="",NOT(ISNUMBER(L11))),0,IF(VALUE(F11)<VALUE(LEFT(TEXT(L11,"00000000"),6)),1,0)) | AE11: =IF(OR(M11="",NOT(ISNUMBER(M11))),0,IF(VALUE(F11)<VALUE(LEFT(TEXT(M11,"00000000"),6)),1,0)) | AF11: =IF(AND(AD11=0,AE11=0),1,0) | AG11: =IF(ISNUMBER(X11),X11,IFERROR(VALUE(LEFT(TEXT(J11,"00000000"),4)),"")) | AH11: =IFERROR(XLOOKUP(AG11,Vintage_Rates!$A$2:$A$1000,Vintage_Rates!$B$2:$B$1000,""),"") | AI11: =IF(ISNUMBER(Y11),Y11,IFERROR((G11-AH11)*100,"")) | AJ11: =IF(ISNUMBER(V11),V11,IFERROR(XLOOKUP(VALUE(F11),PLC_Rates!$A$2:$A$1000,PLC_Rates!$B$2:$B$1000,""),"")) | AK11: =IF(ISNUMBER(Z11),Z11,IF(AE11=0,0,MAX(0,MIN(10,((VALUE(LEFT(TEXT(M11,"00000000"),4))-VALUE(LEFT(F11,4)))*12+(VALUE(MID(TEXT(M11,"00000000"),5,2))-VALUE(MID(F11,5,2))))/12)))) | AL11: =IFERROR(G11*100-AJ11,"") | AM11: =IFERROR(G11*100-(AJ11+(1+AK11)*12.5),"") | AN11: =IFERROR(MIN(H11/1000000,100),"") | AO11: =IFERROR(INDEX(FHA_Lookup!$B$2:$B$11,MATCH(TRUE,ISNUMBER(SEARCH(FHA_Lookup!$A$2:$A$11,UPPER(SUBSTITUTE(O11," ","")))),0)),"OTHER") | AP11: =IFERROR(INDEX(FHA_Lookup!$C$2:$C$11,MATCH(TRUE,ISNUMBER(SEARCH(FHA_Lookup!$A$2:$A$11,UPPER(SUBSTITUTE(O11," ","")))),0)),"OTHER") | AQ11: =IF(AP11="NC",1,0) | AR11: =IF(UPPER(TRIM(P11))="AFF",1,0) | AS11: =IF(UPPER(TRIM(P11))="BAF",1,0) | AT11: =IF(UPPER(TRIM(P11))="MKT",1,0) | AU11: =IF(AO11="221d4",1,0) | AV11: =IF(AO11="223a7",1,0) | AW11: =IF(AO11="232",1,0) | AX11: =IF(AO11="538",1,0) | AY11: =IF(AO11="241",1,0) | AZ11: =IF(AO11="220",1,0) | BA11: =IF(AO11="OTHER",1,0) | BB11: =IF(UPPER(TRIM(C11))="LM",1,0) | BC11: =IF(UPPER(TRIM(C11))="PN",1,0) | BD11: =IF(UPPER(TRIM(C11))="LS",1,0) | BE11: =IF(UPPER(TRIM(C11))="RX",1,0) | BF11: =IFERROR((Parameters!$C$6*AM11+Parameters!$C$7*MAX(AM11-(-150),0)+Parameters!$C$8*MAX(AM11-(-50),0)+Parameters!$C$9*MAX(AM11-(0),0)+Parameters!$C$10*MAX(AM11-(50),0)+Parameters!$C$11*MAX(AM11-(100),0)+Parameters!$C$12*MAX(AM11-(150),0)+Parameters!$C$13*MAX(AM11-(250),0)),0) | BG11: =IFERROR((Parameters!$C$14*AA11+Parameters!$C$15*MAX(AA11-(12),0)+Parameters!$C$16*MAX(AA11-(36),0)+Parameters!$C$17*MAX(AA11-(60),0)+Parameters!$C$18*MAX(AA11-(84),0)+Parameters!$C$19*MAX(AA11-(120),0)+Parameters!$C$20*MAX(AA11-(180),0)),0) | BH11: =IFERROR((Parameters!$C$21*AK11+Parameters!$C$22*MAX(AK11-(0),0)+Parameters!$C$23*MAX(AK11-(2),0)+Parameters!$C$24*MAX(AK11-(5),0)+Parameters!$C$25*MAX(AK11-(8),0)),0) | BI11: =IFERROR((Parameters!$C$26*AI11+Parameters!$C$27*MAX(AI11-(-100),0)+Parameters!$C$28*MAX(AI11-(-25),0)+Parameters!$C$29*MAX(AI11-(25),0)+Parameters!$C$30*MAX(AI11-(100),0)),0) | BJ11: =IFERROR((Parameters!$C$31*AN11+Parameters!$C$32*MAX(AN11-(2),0)+Parameters!$C$33*MAX(AN11-(10),0)+Parameters!$C$34*MAX(AN11-(25),0)),0) | BK11: =IFERROR((Parameters!$C$35*AB11+Parameters!$C$36*MAX(AB11-(12),0)+Parameters!$C$37*MAX(AB11-(24),0)+Parameters!$C$38*MAX(AB11-(60),0)),0) | BL11: =IFERROR((Parameters!$C$39*AC11+Parameters!$C$40*MAX(AC11-(6),0)+Parameters!$C$41*MAX(AC11-(12),0)+Parameters!$C$42*MAX(AC11-(24),0)),0) | BM11: =IFERROR(Parameters!$C$43*(MAX(AM11,0)*MIN(MAX(AK11,0),10))/100,0) | BN11: =Parameters!$C$44*AE11 | BO11: =Parameters!$C$45*AU11 + Parameters!$C$46*AV11 + Parameters!$C$47*AW11 + Parameters!$C$48*AX11 + Parameters!$C$49*AY11 + Parameters!$C$50*AZ11 + Parameters!$C$51*BA11 | BP11: =Parameters!$C$52*AQ11 | BQ11: =Parameters!$C$53*AR11+Parameters!$C$54*AS11+Parameters!$C$55*AT11 | BR11: =Parameters!$C$56*BB11+Parameters!$C$57*BC11+Parameters!$C$58*BD11+Parameters!$C$59*BE11 | BS11: =Parameters!$B$2 | BT11: =BS11+BF11 + BG11 + BH11 + BI11 + BJ11 + BK11 + BL11 + BM11 + BN11 + BO11 + BP11 + BQ11 + BR11 | BU11: =IF(AD11=1,0,1/(1+EXP(-BT11))*Parameters!$B$3) | BV11: =(1-(1-BU11)^12)*100 | BW11: =IF(AD11=1,0,(1-(1-1/(1+EXP(-Parameters!$B$2)))^12)*100) | BX11: =IF(AD11=1,0,BV11-(1-(1-(1/(1+EXP(-(BT11-BF11)))*Parameters!$B$3))^12)*100) | BY11: =IF(AD11=1,0,BV11-(1-(1-(1/(1+EXP(-(BT11-BG11)))*Parameters!$B$3))^12)*100) | BZ11: =IF(AD11=1,0,BV11-(1-(1-(1/(1+EXP(-(BT11-BH11)))*Parameters!$B$3))^12)*100) | CA11: =IF(AD11=1,0,BV11-(1-(1-(1/(1+EXP(-(BT11-BI11)))*Parameters!$B$3))^12)*100) | CB11: =IF(AD11=1,0,BV11-(1-(1-(1/(1+EXP(-(BT11-BJ11)))*Parameters!$B$3))^12)*100) | CC11: =IF(AD11=1,0,BV11-(1-(1-(1/(1+EXP(-(BT11-BK11)))*Parameters!$B$3))^12)*100) | CD11: =IF(AD11=1,0,BV11-(1-(1-(1/(1+EXP(-(BT11-BL11)))*Parameters!$B$3))^12)*100) | CE11: =IF(AD11=1,0,BV11-(1-(1-(1/(1+EXP(-(BT11-BM11)))*Parameters!$B$3))^12)*100) | CF11: =IF(AD11=1,0,BV11-(1-(1-(1/(1+EXP(-(BT11-BN11)))*Parameters!$B$3))^12)*100) | CG11: =IF(AD11=1,0,BV11-(1-(1-(1/(1+EXP(-(BT11-BO11)))*Parameters!$B$3))^12)*100) | CH11: =IF(AD11=1,0,BV11-(1-(1-(1/(1+EXP(-(BT11-BP11)))*Parameters!$B$3))^12)*100) | CI11: =IF(AD11=1,0,BV11-(1-(1-(1/(1+EXP(-(BT11-BQ11)))*Parameters!$B$3))^12)*100) | CJ11: =IF(AD11=1,0,BV11-(1-(1-(1/(1+EXP(-(BT11-BR11)))*Parameters!$B$3))^12)*100)
